[2025-03-07T14:04:57.883+0000] {local_task_job_runner.py:123} INFO - ::group::Pre task execution logs
[2025-03-07T14:04:57.904+0000] {taskinstance.py:2614} INFO - Dependencies all met for dep_context=non-requeueable deps ti=<TaskInstance: our_first_dag.second_task manual__2025-03-07T14:00:51.357697+00:00 [queued]>
[2025-03-07T14:04:57.913+0000] {taskinstance.py:2614} INFO - Dependencies all met for dep_context=requeueable deps ti=<TaskInstance: our_first_dag.second_task manual__2025-03-07T14:00:51.357697+00:00 [queued]>
[2025-03-07T14:04:57.914+0000] {taskinstance.py:2867} INFO - Starting attempt 3 of 5
[2025-03-07T14:04:57.928+0000] {taskinstance.py:2890} INFO - Executing <Task(BashOperator): second_task> on 2025-03-07 14:00:51.357697+00:00
[2025-03-07T14:04:57.939+0000] {standard_task_runner.py:104} INFO - Running: ['***', 'tasks', 'run', 'our_first_dag', 'second_task', 'manual__2025-03-07T14:00:51.357697+00:00', '--job-id', '20', '--raw', '--subdir', 'DAGS_FOLDER/our_first_dag.py', '--cfg-path', '/tmp/tmpwwtcqbl0']
[2025-03-07T14:04:57.941+0000] {standard_task_runner.py:105} INFO - Job 20: Subtask second_task
[2025-03-07T14:04:57.943+0000] {logging_mixin.py:190} WARNING - /home/***/.local/lib/python3.12/site-packages/***/task/task_runner/standard_task_runner.py:70 DeprecationWarning: This process (pid=80465) is multi-threaded, use of fork() may lead to deadlocks in the child.
[2025-03-07T14:04:57.943+0000] {standard_task_runner.py:72} INFO - Started process 80517 to run task
[2025-03-07T14:04:57.985+0000] {task_command.py:467} INFO - Running <TaskInstance: our_first_dag.second_task manual__2025-03-07T14:00:51.357697+00:00 [running]> on host 9462f8147d13
[2025-03-07T14:04:58.061+0000] {taskinstance.py:3134} INFO - Exporting env vars: AIRFLOW_CTX_DAG_OWNER='***' AIRFLOW_CTX_DAG_ID='our_first_dag' AIRFLOW_CTX_TASK_ID='second_task' AIRFLOW_CTX_EXECUTION_DATE='2025-03-07T14:00:51.357697+00:00' AIRFLOW_CTX_TRY_NUMBER='3' AIRFLOW_CTX_DAG_RUN_ID='manual__2025-03-07T14:00:51.357697+00:00'
[2025-03-07T14:04:58.062+0000] {logging_mixin.py:190} INFO - Task instance is in running state
[2025-03-07T14:04:58.063+0000] {logging_mixin.py:190} INFO -  Previous state of the Task instance: queued
[2025-03-07T14:04:58.063+0000] {logging_mixin.py:190} INFO - Current task name:second_task state:running start_date:2025-03-07 14:04:57.905141+00:00
[2025-03-07T14:04:58.063+0000] {logging_mixin.py:190} INFO - Dag name:our_first_dag and current dag run status:running
[2025-03-07T14:04:58.064+0000] {taskinstance.py:732} INFO - ::endgroup::
[2025-03-07T14:04:58.064+0000] {subprocess.py:78} INFO - Tmp dir root location: /tmp
[2025-03-07T14:04:58.065+0000] {subprocess.py:88} INFO - Running command: ['/usr/bin/bash', '-c', "echo, I'm task two"]
[2025-03-07T14:04:58.078+0000] {subprocess.py:99} INFO - Output:
[2025-03-07T14:04:58.079+0000] {subprocess.py:106} INFO - /usr/bin/bash: -c: line 1: unexpected EOF while looking for matching `''
[2025-03-07T14:04:58.080+0000] {subprocess.py:110} INFO - Command exited with return code 2
[2025-03-07T14:04:58.089+0000] {taskinstance.py:3313} ERROR - Task failed with exception
Traceback (most recent call last):
  File "/home/airflow/.local/lib/python3.12/site-packages/airflow/models/taskinstance.py", line 768, in _execute_task
    result = _execute_callable(context=context, **execute_callable_kwargs)
             ^^^^^^^^^^^^^^^^^^^^^^^^^^^^^^^^^^^^^^^^^^^^^^^^^^^^^^^^^^^^^
  File "/home/airflow/.local/lib/python3.12/site-packages/airflow/models/taskinstance.py", line 734, in _execute_callable
    return ExecutionCallableRunner(
           ^^^^^^^^^^^^^^^^^^^^^^^^
  File "/home/airflow/.local/lib/python3.12/site-packages/airflow/utils/operator_helpers.py", line 252, in run
    return self.func(*args, **kwargs)
           ^^^^^^^^^^^^^^^^^^^^^^^^^^
  File "/home/airflow/.local/lib/python3.12/site-packages/airflow/models/baseoperator.py", line 424, in wrapper
    return func(self, *args, **kwargs)
           ^^^^^^^^^^^^^^^^^^^^^^^^^^^
  File "/home/airflow/.local/lib/python3.12/site-packages/airflow/operators/bash.py", line 276, in execute
    raise AirflowException(
airflow.exceptions.AirflowException: Bash command failed. The command returned a non-zero exit code 2.
[2025-03-07T14:04:58.096+0000] {logging_mixin.py:190} INFO - Task instance in failure state
[2025-03-07T14:04:58.096+0000] {logging_mixin.py:190} INFO - Task start:2025-03-07 14:04:57.905141+00:00 end:2025-03-07 14:04:58.095752+00:00 duration:0.190611
[2025-03-07T14:04:58.097+0000] {logging_mixin.py:190} INFO - Task:<Task(BashOperator): second_task> dag:<DAG: our_first_dag> dagrun:<DagRun our_first_dag @ 2025-03-07 14:00:51.357697+00:00: manual__2025-03-07T14:00:51.357697+00:00, state:running, queued_at: 2025-03-07 14:00:51.364809+00:00. externally triggered: True>
[2025-03-07T14:04:58.097+0000] {logging_mixin.py:190} INFO - Failure caused by Bash command failed. The command returned a non-zero exit code 2.
[2025-03-07T14:04:58.097+0000] {taskinstance.py:1226} INFO - Marking task as UP_FOR_RETRY. dag_id=our_first_dag, task_id=second_task, run_id=manual__2025-03-07T14:00:51.357697+00:00, execution_date=20250307T140051, start_date=20250307T140457, end_date=20250307T140458
[2025-03-07T14:04:58.123+0000] {taskinstance.py:341} INFO - ::group::Post task execution logs
[2025-03-07T14:04:58.124+0000] {standard_task_runner.py:124} ERROR - Failed to execute job 20 for task second_task (Bash command failed. The command returned a non-zero exit code 2.; 80517)
Traceback (most recent call last):
  File "/home/airflow/.local/lib/python3.12/site-packages/airflow/task/task_runner/standard_task_runner.py", line 117, in _start_by_fork
    ret = args.func(args, dag=self.dag)
          ^^^^^^^^^^^^^^^^^^^^^^^^^^^^^
  File "/home/airflow/.local/lib/python3.12/site-packages/airflow/cli/cli_config.py", line 49, in command
    return func(*args, **kwargs)
           ^^^^^^^^^^^^^^^^^^^^^
  File "/home/airflow/.local/lib/python3.12/site-packages/airflow/utils/cli.py", line 116, in wrapper
    return f(*args, **kwargs)
           ^^^^^^^^^^^^^^^^^^
  File "/home/airflow/.local/lib/python3.12/site-packages/airflow/cli/commands/task_command.py", line 483, in task_run
    task_return_code = _run_task_by_selected_method(args, _dag, ti)
                       ^^^^^^^^^^^^^^^^^^^^^^^^^^^^^^^^^^^^^^^^^^^^
  File "/home/airflow/.local/lib/python3.12/site-packages/airflow/cli/commands/task_command.py", line 256, in _run_task_by_selected_method
    return _run_raw_task(args, ti)
           ^^^^^^^^^^^^^^^^^^^^^^^
  File "/home/airflow/.local/lib/python3.12/site-packages/airflow/cli/commands/task_command.py", line 341, in _run_raw_task
    return ti._run_raw_task(
           ^^^^^^^^^^^^^^^^^
  File "/home/airflow/.local/lib/python3.12/site-packages/airflow/utils/session.py", line 97, in wrapper
    return func(*args, session=session, **kwargs)
           ^^^^^^^^^^^^^^^^^^^^^^^^^^^^^^^^^^^^^^
  File "/home/airflow/.local/lib/python3.12/site-packages/airflow/models/taskinstance.py", line 3006, in _run_raw_task
    return _run_raw_task(
           ^^^^^^^^^^^^^^
  File "/home/airflow/.local/lib/python3.12/site-packages/airflow/models/taskinstance.py", line 274, in _run_raw_task
    TaskInstance._execute_task_with_callbacks(
  File "/home/airflow/.local/lib/python3.12/site-packages/airflow/models/taskinstance.py", line 3161, in _execute_task_with_callbacks
    result = self._execute_task(context, task_orig)
             ^^^^^^^^^^^^^^^^^^^^^^^^^^^^^^^^^^^^^^
  File "/home/airflow/.local/lib/python3.12/site-packages/airflow/models/taskinstance.py", line 3185, in _execute_task
    return _execute_task(self, context, task_orig)
           ^^^^^^^^^^^^^^^^^^^^^^^^^^^^^^^^^^^^^^^
  File "/home/airflow/.local/lib/python3.12/site-packages/airflow/models/taskinstance.py", line 768, in _execute_task
    result = _execute_callable(context=context, **execute_callable_kwargs)
             ^^^^^^^^^^^^^^^^^^^^^^^^^^^^^^^^^^^^^^^^^^^^^^^^^^^^^^^^^^^^^
  File "/home/airflow/.local/lib/python3.12/site-packages/airflow/models/taskinstance.py", line 734, in _execute_callable
    return ExecutionCallableRunner(
           ^^^^^^^^^^^^^^^^^^^^^^^^
  File "/home/airflow/.local/lib/python3.12/site-packages/airflow/utils/operator_helpers.py", line 252, in run
    return self.func(*args, **kwargs)
           ^^^^^^^^^^^^^^^^^^^^^^^^^^
  File "/home/airflow/.local/lib/python3.12/site-packages/airflow/models/baseoperator.py", line 424, in wrapper
    return func(self, *args, **kwargs)
           ^^^^^^^^^^^^^^^^^^^^^^^^^^^
  File "/home/airflow/.local/lib/python3.12/site-packages/airflow/operators/bash.py", line 276, in execute
    raise AirflowException(
airflow.exceptions.AirflowException: Bash command failed. The command returned a non-zero exit code 2.
[2025-03-07T14:04:58.157+0000] {local_task_job_runner.py:266} INFO - Task exited with return code 1
[2025-03-07T14:04:58.178+0000] {taskinstance.py:3901} INFO - 0 downstream tasks scheduled from follow-on schedule check
[2025-03-07T14:04:58.180+0000] {local_task_job_runner.py:245} INFO - ::endgroup::
